Preparing database...
Year 2018 to current date is seleted.
Database preparation successful.

Start downloading filings. This will take a while...

Error in downloading this file. https://www.sec.gov/Archives/edgar/data/1694665/0001193125-18-116927-index.htm
Error in downloading this file. https://www.sec.gov/Archives/edgar/data/878560/0000000000-18-014217-index.htm
This program has run for 0.02 hours, and downloaded 279 filings, at a rate of 4.65 filings per second.
279/501550 filings have been downloaded: 0.06% complete. Estimated time for completion: 1 day, 5:58:08.

Error in downloading this file. https://www.sec.gov/Archives/edgar/data/1511699/0000894189-18-002390-index.htm
Error in downloading this file. https://www.sec.gov/Archives/edgar/data/1114446/0001114446-18-004191-index.htm
This program has run for 0.03 hours, and downloaded 585 filings, at a rate of 4.87 filings per second.
585/501550 filings have been downloaded: 0.12% complete. Estimated time for completion: 1 day, 4:34:46.

Error in downloading this file. https://www.sec.gov/Archives/edgar/data/1114446/0001114446-18-004221-index.htm
For 100 filings. Process avg: 0.711 seconds. Documents downloading avg: 0.774. 					Iotime avg: 0.011
For 100 filings. Process avg: 0.749 seconds. Documents downloading avg: 0.863. 					Iotime avg: 0.010
For 100 filings. Process avg: 0.754 seconds. Documents downloading avg: 0.847. 					Iotime avg: 0.009
For 100 filings. Process avg: 0.804 seconds. Documents downloading avg: 0.970. 					Iotime avg: 0.013
This program has run for 0.05 hours, and downloaded 870 filings, at a rate of 4.83 filings per second.
870/501550 filings have been downloaded: 0.17% complete. Estimated time for completion: 1 day, 4:49:30.

Error in downloading this file. https://www.sec.gov/Archives/edgar/data/1114446/0001114446-18-004304-index.htm
For 100 filings. Process avg: 0.746 seconds. Documents downloading avg: 1.109. 					Iotime avg: 0.011
Error in downloading this file. https://www.sec.gov/Archives/edgar/data/1566912/0001566912-18-000033-index.htm
For 100 filings. Process avg: 0.771 seconds. Documents downloading avg: 1.327. 					Iotime avg: 0.011
For 100 filings. Process avg: 0.951 seconds. Documents downloading avg: 1.218. 					Iotime avg: 0.008
For 100 filings. Process avg: 0.758 seconds. Documents downloading avg: 1.485. 					Iotime avg: 0.014
For 100 filings. Process avg: 0.995 seconds. Documents downloading avg: 1.309. 					Iotime avg: 0.013
This program has run for 0.07 hours, and downloaded 1163 filings, at a rate of 4.85 filings per second.
1163/501550 filings have been downloaded: 0.23% complete. Estimated time for completion: 1 day, 4:45:01.

Process Process-2:
Traceback (most recent call last):
  File "/Users/michael/anaconda/lib/python3.5/site-packages/requests/packages/urllib3/connection.py", line 142, in _new_conn
    (self.host, self.port), self.timeout, **extra_kw)
  File "/Users/michael/anaconda/lib/python3.5/site-packages/requests/packages/urllib3/util/connection.py", line 67, in create_connection
    for res in socket.getaddrinfo(host, port, 0, socket.SOCK_STREAM):
  File "/Users/michael/anaconda/lib/python3.5/socket.py", line 733, in getaddrinfo
    for res in _socket.getaddrinfo(host, port, family, type, proto, flags):
socket.gaierror: [Errno 8] nodename nor servname provided, or not known

During handling of the above exception, another exception occurred:

Traceback (most recent call last):
  File "/Users/michael/anaconda/lib/python3.5/site-packages/requests/packages/urllib3/connectionpool.py", line 578, in urlopen
    chunked=chunked)
  File "/Users/michael/anaconda/lib/python3.5/site-packages/requests/packages/urllib3/connectionpool.py", line 351, in _make_request
    self._validate_conn(conn)
  File "/Users/michael/anaconda/lib/python3.5/site-packages/requests/packages/urllib3/connectionpool.py", line 814, in _validate_conn
    conn.connect()
  File "/Users/michael/anaconda/lib/python3.5/site-packages/requests/packages/urllib3/connection.py", line 254, in connect
    conn = self._new_conn()
  File "/Users/michael/anaconda/lib/python3.5/site-packages/requests/packages/urllib3/connection.py", line 151, in _new_conn
    self, "Failed to establish a new connection: %s" % e)
requests.packages.urllib3.exceptions.NewConnectionError: <requests.packages.urllib3.connection.VerifiedHTTPSConnection object at 0x111c1b198>: Failed to establish a new connection: [Errno 8] nodename nor servname provided, or not known

During handling of the above exception, another exception occurred:

Traceback (most recent call last):
  File "/Users/michael/anaconda/lib/python3.5/site-packages/requests/adapters.py", line 403, in send
    timeout=timeout
  File "/Users/michael/anaconda/lib/python3.5/site-packages/requests/packages/urllib3/connectionpool.py", line 623, in urlopen
    _stacktrace=sys.exc_info()[2])
  File "/Users/michael/anaconda/lib/python3.5/site-packages/requests/packages/urllib3/util/retry.py", line 281, in increment
    raise MaxRetryError(_pool, url, error or ResponseError(cause))
requests.packages.urllib3.exceptions.MaxRetryError: HTTPSConnectionPool(host='www.sec.gov', port=443): Max retries exceeded with url: /Archives/edgar/data/1632970/9999999995-18-000860-index.htm (Caused by NewConnectionError('<requests.packages.urllib3.connection.VerifiedHTTPSConnection object at 0x111c1b198>: Failed to establish a new connection: [Errno 8] nodename nor servname provided, or not known',))

During handling of the above exception, another exception occurred:

Traceback (most recent call last):
  File "/Users/michael/anaconda/lib/python3.5/multiprocessing/process.py", line 252, in _bootstrap
    self.run()
  File "/Users/michael/anaconda/lib/python3.5/multiprocessing/process.py", line 93, in run
    self._target(*self._args, **self._kwargs)
  File "/Users/michael/Downloads/Side projects/sec crawler/sec v0.6/app.py", line 179, in start_download
    pool.map(download_data_chunk, df) # run the threads
  File "/Users/michael/anaconda/lib/python3.5/multiprocessing/pool.py", line 266, in map
    return self._map_async(func, iterable, mapstar, chunksize).get()
  File "/Users/michael/anaconda/lib/python3.5/multiprocessing/pool.py", line 644, in get
    raise self._value
  File "/Users/michael/anaconda/lib/python3.5/multiprocessing/pool.py", line 119, in worker
    result = (True, func(*args, **kwds))
  File "/Users/michael/anaconda/lib/python3.5/multiprocessing/pool.py", line 44, in mapstar
    return list(map(*args))
  File "/Users/michael/Downloads/Side projects/sec crawler/sec v0.6/app.py", line 132, in download_data_chunk
    urls = get_urls(htm)
  File "/Users/michael/Downloads/Side projects/sec crawler/sec v0.6/app.py", line 86, in get_urls
    soup = BeautifulSoup(requests.get(url).text,'lxml')
  File "/Users/michael/anaconda/lib/python3.5/site-packages/requests/api.py", line 71, in get
    return request('get', url, params=params, **kwargs)
  File "/Users/michael/anaconda/lib/python3.5/site-packages/requests/api.py", line 57, in request
    return session.request(method=method, url=url, **kwargs)
  File "/Users/michael/anaconda/lib/python3.5/site-packages/requests/sessions.py", line 475, in request
    resp = self.send(prep, **send_kwargs)
  File "/Users/michael/anaconda/lib/python3.5/site-packages/requests/sessions.py", line 585, in send
    r = adapter.send(request, **kwargs)
  File "/Users/michael/anaconda/lib/python3.5/site-packages/requests/adapters.py", line 467, in send
    raise ConnectionError(e, request=request)
requests.exceptions.ConnectionError: HTTPSConnectionPool(host='www.sec.gov', port=443): Max retries exceeded with url: /Archives/edgar/data/1632970/9999999995-18-000860-index.htm (Caused by NewConnectionError('<requests.packages.urllib3.connection.VerifiedHTTPSConnection object at 0x111c1b198>: Failed to establish a new connection: [Errno 8] nodename nor servname provided, or not known',))

Downloading complete.
